Workbook

Sheet Description
A1: This sheet compares the new billing query including source stock plate againt the originall billing query without it between '2022-07-24 00:00:00' and '2022-07-25 23:59:59'
A3: Sheet | B3: Description
A4: new_billing_query | B4: The output for the new query with an grouped by an extra stock plate column for the given data range.
A5: original_billing_query | B5: The output for the original query Richard R has been using
A6: Check New Vs Old | B6: Compares the total lane proportion per cost code per study calculated over the two sets of results.
A7: new_billing_query_ungrouped | B7: This is the result of the new billing query without grouping by stock plate in order to carry out a cell by cell comparison with the results from the old query.
A8: Cell By Cell Cmp | B8: This is the result of the cell by cell comparison. Note the only differences showing up are due to rounding errors below 6 decimal places.

Sheet new_billing_query
A1: platform | B1: project_cost_code | C1: study_id | D1: lane_position | E1: batch_id | F1: study_name | G1: stock_plate_barcode | H1: reagent_kit_barcode | I1: sbs_cycle_kit | J1: qc_outcome | K1: v1/1.5 | L1: xp | M1: sp | N1: read1 | O1: read2 | P1: total | Q1: library | R1: num_samples | S1: q20yield
A2: NovaSeq | B2: S0910 | C2: 7068 | D2: 4 | E2: 93296 | F2: Alternative Enzymes 2022 human genomes | I2: 338 | J2: passed | K2: v1.5 | L2: XP | M2: S4 | N2: 151 | O2: 151 | P2: 0.017241379 | Q2: Pre-quality controlled | R2: 1 | S2: 290498475
A3: NovaSeq | B3: S0910 | C3: 7069 | D3: 4 | E3: 93296 | F3: Alternative Enzymes 2022 microbial genomes | I3: 338 | J3: passed | K3: v1.5 | L3: XP | M3: S4 | N3: 151 | O3: 151 | P3: 0.13793103 | Q3: Pre-quality controlled | R3: 8 | S3: 934583.75
A4: NovaSeq | B4: S4240 | C4: 6423 | D4: 1 | E4: 93294 | F4: Functional changes associated with drivers in chronic liver disease (exome) | G4: DN944363E | I4: 338 | J4: passed | K4: v1.5 | L4: XP | M4: S4 | N4: 151 | O4: 151 | P4: 1 | Q4: Twist Pulldown | R4: 16 | S4: 53789815
A5: NovaSeq | B5: S4240 | C5: 6423 | D5: 2 | E5: 93294 | F5: Functional changes associated with drivers in chronic liver disease (exome) | G5: DN944363E | I5: 338 | J5: passed | K5: v1.5 | L5: XP | M5: S4 | N5: 151 | O5: 151 | P5: 0.99999999 | Q5: Twist Pulldown | R5: 22 | S5: 38883371
A6: NovaSeq | B6: S4240 | C6: 6423 | D6: 3 | E6: 93294 | F6: Functional changes associated with drivers in chronic liver disease (exome) | G6: DN944363E | I6: 338 | J6: passed | K6: v1.5 | L6: XP | M6: S4 | N6: 151 | O6: 151 | P6: 0.99999999 | Q6: Twist Pulldown | R6: 22 | S6: 39057516
A7: NovaSeq | B7: S4240 | C7: 6423 | D7: 4 | E7: 93294 | F7: Functional changes associated with drivers in chronic liver disease (exome) | G7: DN944363E | I7: 338 | J7: passed | K7: v1.5 | L7: XP | M7: S4 | N7: 151 | O7: 151 | P7: 0.99999999 | Q7: Twist Pulldown | R7: 22 | S7: 39177372
A8: NovaSeq | B8: S4240 | C8: 6423 | D8: 1 | E8: 93295 | F8: Functional changes associated with drivers in chronic liver disease (exome) | G8: DN944364F | I8: 338 | J8: passed | K8: v1.5 | L8: XP | M8: S4 | N8: 151 | O8: 151 | P8: 0.99999999 | Q8: Twist Pulldown | R8: 26 | S8: 34186340
A9: NovaSeq | B9: S4240 | C9: 6423 | D9: 2 | E9: 93295 | F9: Functional changes associated with drivers in chronic liver disease (exome) | G9: DN944365G | I9: 338 | J9: passed | K9: v1.5 | L9: XP | M9: S4 | N9: 151 | O9: 151 | P9: 0.99999999 | Q9: Twist Pulldown | R9: 13 | S9: 67276807
A10: NovaSeq | B10: S4240 | C10: 6423 | D10: 3 | E10: 93295 | F10: Functional changes associated with drivers in chronic liver disease (exome) | G10: DN944365G | I10: 338 | J10: passed | K10: v1.5 | L10: XP | M10: S4 | N10: 151 | O10: 151 | P10: 0.99999999 | Q10: Twist Pulldown | R10: 17 | S10: 49678905
A11: NovaSeq | B11: S4240 | C11: 6423 | D11: 4 | E11: 93295 | F11: Functional changes associated with drivers in chronic liver disease (exome) | G11: DN944365G | I11: 338 | J11: passed | K11: v1.5 | L11: XP | M11: S4 | N11: 151 | O11: 151 | P11: 0.99999999 | Q11: Twist Pulldown | R11: 17 | S11: 50940392
A12: NovaSeq | B12: S4240 | C12: 6423 | D12: 1 | E12: 93296 | F12: Functional changes associated with drivers in chronic liver disease (exome) | G12: DN944364F | I12: 338 | J12: passed | K12: v1.5 | L12: XP | M12: S4 | N12: 151 | O12: 151 | P12: 1 | Q12: Twist Pulldown | R12: 16 | S12: 57150072
A13: NovaSeq | B13: S4240 | C13: 6423 | D13: 2 | E13: 93296 | F13: Functional changes associated with drivers in chronic liver disease (exome) | G13: DN944364F | I13: 338 | J13: passed | K13: v1.5 | L13: XP | M13: S4 | N13: 151 | O13: 151 | P13: 0.99999999 | Q13: Twist Pulldown | R13: 26 | S13: 35362787
A14: NovaSeq | B14: S4240 | C14: 6423 | D14: 3 | E14: 93296 | F14: Functional changes associated with drivers in chronic liver disease (exome) | G14: DN944364F | I14: 338 | J14: passed | K14: v1.5 | L14: XP | M14: S4 | N14: 151 | O14: 151 | P14: 0.99999999 | Q14: Twist Pulldown | R14: 26 | S14: 34572410
A15: HiSeq | B15: S10332 | C15: 6644 | D15: 1 | E15: 93301 | F15: HCA Bone Marrow Wellcome LEAP RNA | J15: passed | P15: 1 | Q15: Chromium single cell 5 prime | R15: 2 | S15: 4519056
A16: HiSeq | B16: S10332 | C16: 6644 | D16: 2 | E16: 93301 | F16: HCA Bone Marrow Wellcome LEAP RNA | J16: passed | P16: 1 | Q16: Chromium single cell 5 prime | R16: 2 | S16: 4635952.5
A17: NovaSeq | B17: T10274 | C17: 6187 | D17: 1 | E17: 93378 | F17: Heron Project | G17: HT-138729 | I17: 545 | J17: passed | K17: v1.5 | L17: XP | M17: SP | N17: 221 | O17: 201 | P17: 0.24999994 | Q17: Sanger_tailed_artic_v1_384 | R17: 96 | S17: 485371.3
A18: NovaSeq | B18: T10274 | C18: 6187 | D18: 1 | E18: 93378 | F18: Heron Project | G18: HT-138751 | I18: 545 | J18: passed | K18: v1.5 | L18: XP | M18: SP | N18: 221 | O18: 201 | P18: 0.24999994 | Q18: Sanger_tailed_artic_v1_384 | R18: 96 | S18: 347156.91
A19: NovaSeq | B19: T10274 | C19: 6187 | D19: 1 | E19: 93378 | F19: Heron Project | G19: HT-138753 | I19: 545 | J19: passed | K19: v1.5 | L19: XP | M19: SP | N19: 221 | O19: 201 | P19: 0.24999994 | Q19: Sanger_tailed_artic_v1_384 | R19: 96 | S19: 609469.77
A20: NovaSeq | B20: T10274 | C20: 6187 | D20: 1 | E20: 93378 | F20: Heron Project | G20: HT-138803 | I20: 545 | J20: passed | K20: v1.5 | L20: XP | M20: SP | N20: 221 | O20: 201 | P20: 0.24999994 | Q20: Sanger_tailed_artic_v1_384 | R20: 96 | S20: 606000.15
A21: NovaSeq | B21: T10274 | C21: 6187 | D21: 2 | E21: 93378 | F21: Heron Project | G21: HT-138731 | I21: 545 | J21: passed | K21: v1.5 | L21: XP | M21: SP | N21: 221 | O21: 201 | P21: 0.24999994 | Q21: Sanger_tailed_artic_v1_384 | R21: 96 | S21: 508721.14
A22: NovaSeq | B22: T10274 | C22: 6187 | D22: 2 | E22: 93378 | F22: Heron Project | G22: HT-138733 | I22: 545 | J22: passed | K22: v1.5 | L22: XP | M22: SP | N22: 221 | O22: 201 | P22: 0.24999994 | Q22: Sanger_tailed_artic_v1_384 | R22: 96 | S22: 764374.85
A23: NovaSeq | B23: T10274 | C23: 6187 | D23: 2 | E23: 93378 | F23: Heron Project | G23: HT-138802 | I23: 545 | J23: passed | K23: v1.5 | L23: XP | M23: SP | N23: 221 | O23: 201 | P23: 0.24999994 | Q23: Sanger_tailed_artic_v1_384 | R23: 96 | S23: 226603.94
A24: NovaSeq | B24: T10274 | C24: 6187 | D24: 2 | E24: 93378 | F24: Heron Project | G24: HT-138804 | I24: 545 | J24: passed | K24: v1.5 | L24: XP | M24: SP | N24: 221 | O24: 201 | P24: 0.24999994 | Q24: Sanger_tailed_artic_v1_384 | R24: 96 | S24: 724323.1
A25: NovaSeq | B25: T10274 | C25: 6187 | D25: 1 | E25: 93381 | F25: Heron Project | G25: HT-138770 | I25: 545 | J25: passed | K25: v1.5 | L25: XP | M25: SP | N25: 221 | O25: 201 | P25: 0.2513089 | Q25: Sanger_tailed_artic_v1_384 | R25: 96 | S25: 396447.47
A26: NovaSeq | B26: T10274 | C26: 6187 | D26: 1 | E26: 93381 | F26: Heron Project | G26: HT-138790 | I26: 545 | J26: passed | K26: v1.5 | L26: XP | M26: SP | N26: 221 | O26: 201 | P26: 0.2513089 | Q26: Sanger_tailed_artic_v1_384 | R26: 96 | S26: 753657.38
A27: NovaSeq | B27: T10274 | C27: 6187 | D27: 1 | E27: 93381 | F27: Heron Project | G27: HT-138795 | I27: 545 | J27: passed | K27: v1.5 | L27: XP | M27: SP | N27: 221 | O27: 201 | P27: 0.2513089 | Q27: Sanger_tailed_artic_v1_384 | R27: 96 | S27: 551311.33
A28: NovaSeq | B28: T10274 | C28: 6187 | D28: 1 | E28: 93381 | F28: Heron Project | G28: HT-138800 | I28: 545 | J28: passed | K28: v1.5 | L28: XP | M28: SP | N28: 221 | O28: 201 | P28: 0.24607329 | Q28: Sanger_tailed_artic_v1_384 | R28: 94 | S28: 435607.8
... A99: NovaSeq | B99: S4360 | C99: 6595 | D99: 4 | E99: 93352 | F99: HG_WC10162_Birth Cohort_MCS | G99: DN940781C | I99: 330 | J99: passed | K99: v1 | L99: XP | M99: S4 | N99: 101 | O99: 101 | P99: 0.23958332 | Q99: Agilent Pulldown | R99: 23 | S99: 5884306.7
A100: MiSeq | B100: S0910 | C100: 2984 | D100: 1 | E100: 93010 | F100: MQ R and D 2014 | H100: 600V3 | P100: 1 | Q100: Pre-quality controlled | R100: 37 | S100: 126135.22
A101: MiSeq | B101: S0910 | C101: 2984 | D101: 1 | E101: 93080 | F101: MQ R and D 2014 | H101: 600V3 | P101: 0.99999999 | Q101: Pre-quality controlled | R101: 49 | S101: 98693.367
A102: NovaSeq | B102: S0910 | C102: 2984 | D102: 4 | E102: 93296 | F102: MQ R and D 2014 | I102: 338 | J102: passed | K102: v1.5 | L102: XP | M102: S4 | N102: 151 | O102: 151 | P102: 0.84482757 | Q102: Pre-quality controlled | R102: 49 | S102: 10942318
A103: NovaSeq | B103: S10017 | C103: 6778 | D103: 1 | E103: 93242 | F103: Mutational variability in oesophagus in areas of high SCC incidence_WGS | G103: DN640619V | I103: 338 | J103: passed | K103: v1.5 | L103: No XP | M103: S4 | N103: 151 | O103: 151 | P103: 0.08510638 | Q103: Agilent Pulldown | R103: 4
A104: NovaSeq | B104: S10017 | C104: 6778 | D104: 1 | E104: 93242 | F104: Mutational variability in oesophagus in areas of high SCC incidence_WGS | G104: DN866279V | I104: 338 | J104: passed | K104: v1.5 | L104: No XP | M104: S4 | N104: 151 | O104: 151 | P104: 0.21276595 | Q104: Agilent Pulldown | R104: 10
A105: NovaSeq | B105: S10017 | C105: 6778 | D105: 1 | E105: 93242 | F105: Mutational variability in oesophagus in areas of high SCC incidence_WGS | G105: DN866280O | I105: 338 | J105: passed | K105: v1.5 | L105: No XP | M105: S4 | N105: 151 | O105: 151 | P105: 0.14893617 | Q105: Agilent Pulldown | R105: 7
A106: NovaSeq | B106: S10017 | C106: 6778 | D106: 1 | E106: 93242 | F106: Mutational variability in oesophagus in areas of high SCC incidence_WGS | G106: DN919915T | I106: 338 | J106: passed | K106: v1.5 | L106: No XP | M106: S4 | N106: 151 | O106: 151 | P106: 0.08510638 | Q106: Agilent Pulldown | R106: 4
A107: NovaSeq | B107: S10017 | C107: 6778 | D107: 1 | E107: 93242 | F107: Mutational variability in oesophagus in areas of high SCC incidence_WGS | G107: DN948404M | I107: 338 | J107: passed | K107: v1.5 | L107: No XP | M107: S4 | N107: 151 | O107: 151 | P107: 0.46808509 | Q107: Agilent Pulldown | R107: 22
A108: NovaSeq | B108: S10017 | C108: 6778 | D108: 2 | E108: 93242 | F108: Mutational variability in oesophagus in areas of high SCC incidence_WGS | G108: DN640619V | I108: 338 | J108: passed | K108: v1.5 | L108: No XP | M108: S4 | N108: 151 | O108: 151 | P108: 0.08510638 | Q108: Agilent Pulldown | R108: 4
A109: NovaSeq | B109: S10017 | C109: 6778 | D109: 2 | E109: 93242 | F109: Mutational variability in oesophagus in areas of high SCC incidence_WGS | G109: DN866279V | I109: 338 | J109: passed | K109: v1.5 | L109: No XP | M109: S4 | N109: 151 | O109: 151 | P109: 0.21276595 | Q109: Agilent Pulldown | R109: 10
A110: NovaSeq | B110: S10017 | C110: 6778 | D110: 2 | E110: 93242 | F110: Mutational variability in oesophagus in areas of high SCC incidence_WGS | G110: DN866280O | I110: 338 | J110: passed | K110: v1.5 | L110: No XP | M110: S4 | N110: 151 | O110: 151 | P110: 0.14893617 | Q110: Agilent Pulldown | R110: 7
...

Sheet original_billing_query
A1: platform | B1: project_cost_code | C1: study_id | D1: lane_position | E1: batch_id | F1: study_name | G1: reagent_kit_barcode | H1: sbs_cycle_kit | I1: qc_outcome | J1: v1/1.5 | K1: xp | L1: sp | M1: read1 | N1: read2 | O1: total | P1: library | Q1: num_samples | R1: q20yield
A2: NovaSeq | B2: S0910 | C2: 7068 | D2: 4 | E2: 93296 | F2: Alternative Enzymes 2022 human genomes | H2: 338 | I2: passed | J2: v1.5 | K2: XP | L2: S4 | M2: 151 | N2: 151 | O2: 0.017241379 | P2: Pre-quality controlled | Q2: 1 | R2: 290498475
A3: NovaSeq | B3: S0910 | C3: 7069 | D3: 4 | E3: 93296 | F3: Alternative Enzymes 2022 microbial genomes | H3: 338 | I3: passed | J3: v1.5 | K3: XP | L3: S4 | M3: 151 | N3: 151 | O3: 0.13793103 | P3: Pre-quality controlled | Q3: 8 | R3: 934583.75
A4: NovaSeq | B4: S4240 | C4: 6423 | D4: 1 | E4: 93294 | F4: Functional changes associated with drivers in chronic liver disease (exome) | H4: 338 | I4: passed | J4: v1.5 | K4: XP | L4: S4 | M4: 151 | N4: 151 | O4: 1 | P4: Twist Pulldown | Q4: 16 | R4: 53789815
A5: NovaSeq | B5: S4240 | C5: 6423 | D5: 2 | E5: 93294 | F5: Functional changes associated with drivers in chronic liver disease (exome) | H5: 338 | I5: passed | J5: v1.5 | K5: XP | L5: S4 | M5: 151 | N5: 151 | O5: 0.99999999 | P5: Twist Pulldown | Q5: 22 | R5: 38883371
A6: NovaSeq | B6: S4240 | C6: 6423 | D6: 3 | E6: 93294 | F6: Functional changes associated with drivers in chronic liver disease (exome) | H6: 338 | I6: passed | J6: v1.5 | K6: XP | L6: S4 | M6: 151 | N6: 151 | O6: 0.99999999 | P6: Twist Pulldown | Q6: 22 | R6: 39057516
A7: NovaSeq | B7: S4240 | C7: 6423 | D7: 4 | E7: 93294 | F7: Functional changes associated with drivers in chronic liver disease (exome) | H7: 338 | I7: passed | J7: v1.5 | K7: XP | L7: S4 | M7: 151 | N7: 151 | O7: 0.99999999 | P7: Twist Pulldown | Q7: 22 | R7: 39177372
A8: NovaSeq | B8: S4240 | C8: 6423 | D8: 1 | E8: 93295 | F8: Functional changes associated with drivers in chronic liver disease (exome) | H8: 338 | I8: passed | J8: v1.5 | K8: XP | L8: S4 | M8: 151 | N8: 151 | O8: 0.99999999 | P8: Twist Pulldown | Q8: 26 | R8: 34186340
A9: NovaSeq | B9: S4240 | C9: 6423 | D9: 2 | E9: 93295 | F9: Functional changes associated with drivers in chronic liver disease (exome) | H9: 338 | I9: passed | J9: v1.5 | K9: XP | L9: S4 | M9: 151 | N9: 151 | O9: 0.99999999 | P9: Twist Pulldown | Q9: 13 | R9: 67276807
A10: NovaSeq | B10: S4240 | C10: 6423 | D10: 3 | E10: 93295 | F10: Functional changes associated with drivers in chronic liver disease (exome) | H10: 338 | I10: passed | J10: v1.5 | K10: XP | L10: S4 | M10: 151 | N10: 151 | O10: 0.99999999 | P10: Twist Pulldown | Q10: 17 | R10: 49678905
A11: NovaSeq | B11: S4240 | C11: 6423 | D11: 4 | E11: 93295 | F11: Functional changes associated with drivers in chronic liver disease (exome) | H11: 338 | I11: passed | J11: v1.5 | K11: XP | L11: S4 | M11: 151 | N11: 151 | O11: 0.99999999 | P11: Twist Pulldown | Q11: 17 | R11: 50940392
A12: NovaSeq | B12: S4240 | C12: 6423 | D12: 1 | E12: 93296 | F12: Functional changes associated with drivers in chronic liver disease (exome) | H12: 338 | I12: passed | J12: v1.5 | K12: XP | L12: S4 | M12: 151 | N12: 151 | O12: 1 | P12: Twist Pulldown | Q12: 16 | R12: 57150072
A13: NovaSeq | B13: S4240 | C13: 6423 | D13: 2 | E13: 93296 | F13: Functional changes associated with drivers in chronic liver disease (exome) | H13: 338 | I13: passed | J13: v1.5 | K13: XP | L13: S4 | M13: 151 | N13: 151 | O13: 0.99999999 | P13: Twist Pulldown | Q13: 26 | R13: 35362787
A14: NovaSeq | B14: S4240 | C14: 6423 | D14: 3 | E14: 93296 | F14: Functional changes associated with drivers in chronic liver disease (exome) | H14: 338 | I14: passed | J14: v1.5 | K14: XP | L14: S4 | M14: 151 | N14: 151 | O14: 0.99999999 | P14: Twist Pulldown | Q14: 26 | R14: 34572410
A15: HiSeq | B15: S10332 | C15: 6644 | D15: 1 | E15: 93301 | F15: HCA Bone Marrow Wellcome LEAP RNA | I15: passed | O15: 1 | P15: Chromium single cell 5 prime | Q15: 2 | R15: 4519056
A16: HiSeq | B16: S10332 | C16: 6644 | D16: 2 | E16: 93301 | F16: HCA Bone Marrow Wellcome LEAP RNA | I16: passed | O16: 1 | P16: Chromium single cell 5 prime | Q16: 2 | R16: 4635952.5
A17: NovaSeq | B17: T10274 | C17: 6187 | D17: 1 | E17: 93378 | F17: Heron Project | H17: 545 | I17: passed | J17: v1.5 | K17: XP | L17: SP | M17: 221 | N17: 201 | O17: 0.99999974 | P17: Sanger_tailed_artic_v1_384 | Q17: 384 | R17: 511999.53
A18: NovaSeq | B18: T10274 | C18: 6187 | D18: 2 | E18: 93378 | F18: Heron Project | H18: 545 | I18: passed | J18: v1.5 | K18: XP | L18: SP | M18: 221 | N18: 201 | O18: 0.99999974 | P18: Sanger_tailed_artic_v1_384 | Q18: 384 | R18: 556005.76
A19: NovaSeq | B19: T10274 | C19: 6187 | D19: 1 | E19: 93381 | F19: Heron Project | H19: 545 | I19: passed | J19: v1.5 | K19: XP | L19: SP | M19: 221 | N19: 201 | O19: 0.99999998 | P19: Sanger_tailed_artic_v1_384 | Q19: 382 | R19: 534772.48
A20: NovaSeq | B20: T10274 | C20: 6187 | D20: 2 | E20: 93381 | F20: Heron Project | H20: 545 | I20: passed | J20: v1.5 | K20: XP | L20: SP | M20: 221 | N20: 201 | O20: 0.99999974 | P20: Sanger_tailed_artic_v1_384 | Q20: 384 | R20: 474191.07
A21: NovaSeq | B21: T10274 | C21: 6187 | D21: 1 | E21: 93382 | F21: Heron Project | H21: 545 | I21: passed | J21: v1.5 | K21: XP | L21: SP | M21: 221 | N21: 201 | O21: 0.99999974 | P21: Sanger_tailed_artic_v1_384 | Q21: 384 | R21: 557385.74
A22: NovaSeq | B22: T10274 | C22: 6187 | D22: 2 | E22: 93382 | F22: Heron Project | H22: 545 | I22: passed | J22: v1.5 | K22: XP | L22: SP | M22: 221 | N22: 201 | O22: 0.99999974 | P22: Sanger_tailed_artic_v1_384 | Q22: 384 | R22: 558268.67
A23: NovaSeq | B23: T10274 | C23: 6187 | D23: 1 | E23: 93383 | F23: Heron Project | H23: 545 | I23: passed | J23: v1.5 | K23: XP | L23: SP | M23: 221 | N23: 201 | O23: 0.99999974 | P23: Sanger_tailed_artic_v1_384 | Q23: 384 | R23: 515708.97
A24: NovaSeq | B24: T10274 | C24: 6187 | D24: 2 | E24: 93383 | F24: Heron Project | H24: 545 | I24: passed | J24: v1.5 | K24: XP | L24: SP | M24: 221 | N24: 201 | O24: 0.99999974 | P24: Sanger_tailed_artic_v1_384 | Q24: 384 | R24: 556082.06
A25: NovaSeq | B25: T10274 | C25: 6187 | D25: 1 | E25: 93384 | F25: Heron Project | H25: 545 | I25: passed | J25: v1.5 | K25: XP | L25: SP | M25: 221 | N25: 201 | O25: 0.99999974 | P25: Sanger_tailed_artic_v1_384 | Q25: 384 | R25: 541942.21
A26: NovaSeq | B26: T10274 | C26: 6187 | D26: 2 | E26: 93384 | F26: Heron Project | H26: 545 | I26: passed | J26: v1.5 | K26: XP | L26: SP | M26: 221 | N26: 201 | O26: 0.99999974 | P26: Sanger_tailed_artic_v1_384 | Q26: 384 | R26: 540373.43
A27: NovaSeq | B27: S4216 | C27: 6595 | D27: 1 | E27: 93290 | F27: HG_WC10162_Birth Cohort_MCS | H27: 330 | I27: passed | J27: v1 | K27: XP | L27: S4 | M27: 101 | N27: 101 | O27: 0.99999994 | P27: Agilent Pulldown | Q27: 96 | R27: 5997014.7
A28: NovaSeq | B28: S4216 | C28: 6595 | D28: 2 | E28: 93290 | F28: HG_WC10162_Birth Cohort_MCS | H28: 330 | I28: passed | J28: v1 | K28: XP | L28: S4 | M28: 101 | N28: 101 | O28: 0.99999994 | P28: Agilent Pulldown | Q28: 96 | R28: 5997183.7
... A38: NovaSeq | B38: S4360 | C38: 6595 | D38: 4 | E38: 93352 | F38: HG_WC10162_Birth Cohort_MCS | H38: 330 | I38: passed | J38: v1 | K38: XP | L38: S4 | M38: 101 | N38: 101 | O38: 0.99999994 | P38: Agilent Pulldown | Q38: 96 | R38: 5879089.7
A39: MiSeq | B39: S0910 | C39: 2984 | D39: 1 | E39: 93010 | F39: MQ R and D 2014 | G39: 600V3 | O39: 1 | P39: Pre-quality controlled | Q39: 37 | R39: 126135.22
A40: MiSeq | B40: S0910 | C40: 2984 | D40: 1 | E40: 93080 | F40: MQ R and D 2014 | G40: 600V3 | O40: 0.99999999 | P40: Pre-quality controlled | Q40: 49 | R40: 98693.367
A41: NovaSeq | B41: S0910 | C41: 2984 | D41: 4 | E41: 93296 | F41: MQ R and D 2014 | H41: 338 | I41: passed | J41: v1.5 | K41: XP | L41: S4 | M41: 151 | N41: 151 | O41: 0.84482757 | P41: Pre-quality controlled | Q41: 49 | R41: 10942318
A42: NovaSeq | B42: S10017 | C42: 6778 | D42: 1 | E42: 93242 | F42: Mutational variability in oesophagus in areas of high SCC incidence_WGS | H42: 338 | I42: passed | J42: v1.5 | K42: No XP | L42: S4 | M42: 151 | N42: 151 | O42: 1 | P42: Agilent Pulldown | Q42: 25
A43: NovaSeq | B43: S10017 | C43: 6778 | D43: 2 | E43: 93242 | F43: Mutational variability in oesophagus in areas of high SCC incidence_WGS | H43: 338 | I43: passed | J43: v1.5 | K43: No XP | L43: S4 | M43: 151 | N43: 151 | O43: 1 | P43: Agilent Pulldown | Q43: 25
A44: NovaSeq | B44: S10017 | C44: 6778 | D44: 3 | E44: 93242 | F44: Mutational variability in oesophagus in areas of high SCC incidence_WGS | H44: 338 | I44: passed | J44: v1.5 | K44: No XP | L44: S4 | M44: 151 | N44: 151 | O44: 1 | P44: Agilent Pulldown | Q44: 25
A45: NovaSeq | B45: S10017 | C45: 6778 | D45: 4 | E45: 93242 | F45: Mutational variability in oesophagus in areas of high SCC incidence_WGS | H45: 338 | I45: passed | J45: v1.5 | K45: No XP | L45: S4 | M45: 151 | N45: 151 | O45: 1 | P45: Agilent Pulldown | Q45: 25
A46: NovaSeq | B46: T10274 | C46: 6940 | D46: 1 | E46: 93379 | F46: RVI Programme - Heron Library | H46: 545 | I46: passed | J46: v1.5 | K46: XP | L46: SP | M46: 221 | N46: 201 | O46: 0.99999974 | P46: Sanger_tailed_artic_v1_384 | Q46: 384 | R46: 565047.62
A47: NovaSeq | B47: T10274 | C47: 6940 | D47: 2 | E47: 93379 | F47: RVI Programme - Heron Library | H47: 545 | I47: passed | J47: v1.5 | K47: XP | L47: SP | M47: 221 | N47: 201 | O47: 0.99999974 | P47: Sanger_tailed_artic_v1_384 | Q47: 384 | R47: 561630.7

Sheet Check New Vs Old
A1: New Billing Query Summed | F1: Old Billing Query Summed | J1: Match Check (6 d.p.)
A2: project_cost_code | B2: study_id | C2: SUM of total | F2: project_cost_code | G2: study_id | H2: SUM of total
A3: S0910 | B3: 2984 | C3: 2.8448276 | F3: S0910 | G3: 2984 | H3: 2.8448276 | J3: =ROUND(C3,6)=ROUND(H3,6) -> TRUE
B4: 7068 | C4: 0.017241379 | G4: 7068 | H4: 0.017241379 | J4: =ROUND(C4,6)=ROUND(H4,6) -> TRUE
B5: 7069 | C5: 0.13793103 | G5: 7069 | H5: 0.13793103 | J5: =ROUND(C5,6)=ROUND(H5,6) -> TRUE
A6: S10017 | B6: 6778 | C6: 3.9999999 | F6: S10017 | G6: 6778 | H6: 4 | J6: =ROUND(C6,6)=ROUND(H6,6) -> TRUE
A7: S10332 | B7: 6644 | C7: 2 | F7: S10332 | G7: 6644 | H7: 2 | J7: =ROUND(C7,6)=ROUND(H7,6) -> TRUE
A8: S4216 | B8: 6595 | C8: 10.999999 | F8: S4216 | G8: 6595 | H8: 10.999999 | J8: =ROUND(C8,6)=ROUND(H8,6) -> TRUE
A9: S4240 | B9: 6423 | C9: 11 | F9: S4240 | G9: 6423 | H9: 11 | J9: =ROUND(C9,6)=ROUND(H9,6) -> TRUE
A10: S4360 | B10: 6595 | C10: 0.99999994 | F10: S4360 | G10: 6595 | H10: 0.99999994 | J10: =ROUND(C10,6)=ROUND(H10,6) -> TRUE
A11: T10274 | B11: 6187 | C11: 9.9999977 | F11: T10274 | G11: 6187 | H11: 9.9999977 | J11: =ROUND(C11,6)=ROUND(H11,6) -> TRUE
B12: 6940 | C12: 1.9999995 | G12: 6940 | H12: 1.9999995 | J12: =ROUND(C12,6)=ROUND(H12,6) -> TRUE

Sheet new_billing_query_ungrouped
A1: platform | B1: project_cost_code | C1: study_id | D1: lane_position | E1: batch_id | F1: study_name | G1: reagent_kit_barcode | H1: sbs_cycle_kit | I1: qc_outcome | J1: v1/1.5 | K1: xp | L1: sp | M1: read1 | N1: read2 | O1: total | P1: library | Q1: num_samples | R1: q20yield
A2: NovaSeq | B2: S0910 | C2: 7068 | D2: 4 | E2: 93296 | F2: Alternative Enzymes 2022 human genomes | H2: 338 | I2: passed | J2: v1.5 | K2: XP | L2: S4 | M2: 151 | N2: 151 | O2: 0.017241379 | P2: Pre-quality controlled | Q2: 1 | R2: 290498475
A3: NovaSeq | B3: S0910 | C3: 7069 | D3: 4 | E3: 93296 | F3: Alternative Enzymes 2022 microbial genomes | H3: 338 | I3: passed | J3: v1.5 | K3: XP | L3: S4 | M3: 151 | N3: 151 | O3: 0.13793103 | P3: Pre-quality controlled | Q3: 8 | R3: 934583.75
A4: NovaSeq | B4: S4240 | C4: 6423 | D4: 1 | E4: 93294 | F4: Functional changes associated with drivers in chronic liver disease (exome) | H4: 338 | I4: passed | J4: v1.5 | K4: XP | L4: S4 | M4: 151 | N4: 151 | O4: 1 | P4: Twist Pulldown | Q4: 16 | R4: 53789815
A5: NovaSeq | B5: S4240 | C5: 6423 | D5: 2 | E5: 93294 | F5: Functional changes associated with drivers in chronic liver disease (exome) | H5: 338 | I5: passed | J5: v1.5 | K5: XP | L5: S4 | M5: 151 | N5: 151 | O5: 0.99999999 | P5: Twist Pulldown | Q5: 22 | R5: 38883371
A6: NovaSeq | B6: S4240 | C6: 6423 | D6: 3 | E6: 93294 | F6: Functional changes associated with drivers in chronic liver disease (exome) | H6: 338 | I6: passed | J6: v1.5 | K6: XP | L6: S4 | M6: 151 | N6: 151 | O6: 0.99999999 | P6: Twist Pulldown | Q6: 22 | R6: 39057516
A7: NovaSeq | B7: S4240 | C7: 6423 | D7: 4 | E7: 93294 | F7: Functional changes associated with drivers in chronic liver disease (exome) | H7: 338 | I7: passed | J7: v1.5 | K7: XP | L7: S4 | M7: 151 | N7: 151 | O7: 0.99999999 | P7: Twist Pulldown | Q7: 22 | R7: 39177372
A8: NovaSeq | B8: S4240 | C8: 6423 | D8: 1 | E8: 93295 | F8: Functional changes associated with drivers in chronic liver disease (exome) | H8: 338 | I8: passed | J8: v1.5 | K8: XP | L8: S4 | M8: 151 | N8: 151 | O8: 0.99999999 | P8: Twist Pulldown | Q8: 26 | R8: 34186340
A9: NovaSeq | B9: S4240 | C9: 6423 | D9: 2 | E9: 93295 | F9: Functional changes associated with drivers in chronic liver disease (exome) | H9: 338 | I9: passed | J9: v1.5 | K9: XP | L9: S4 | M9: 151 | N9: 151 | O9: 0.99999999 | P9: Twist Pulldown | Q9: 13 | R9: 67276807
A10: NovaSeq | B10: S4240 | C10: 6423 | D10: 3 | E10: 93295 | F10: Functional changes associated with drivers in chronic liver disease (exome) | H10: 338 | I10: passed | J10: v1.5 | K10: XP | L10: S4 | M10: 151 | N10: 151 | O10: 0.99999999 | P10: Twist Pulldown | Q10: 17 | R10: 49678905
A11: NovaSeq | B11: S4240 | C11: 6423 | D11: 4 | E11: 93295 | F11: Functional changes associated with drivers in chronic liver disease (exome) | H11: 338 | I11: passed | J11: v1.5 | K11: XP | L11: S4 | M11: 151 | N11: 151 | O11: 0.99999999 | P11: Twist Pulldown | Q11: 17 | R11: 50940392
A12: NovaSeq | B12: S4240 | C12: 6423 | D12: 1 | E12: 93296 | F12: Functional changes associated with drivers in chronic liver disease (exome) | H12: 338 | I12: passed | J12: v1.5 | K12: XP | L12: S4 | M12: 151 | N12: 151 | O12: 1 | P12: Twist Pulldown | Q12: 16 | R12: 57150072
A13: NovaSeq | B13: S4240 | C13: 6423 | D13: 2 | E13: 93296 | F13: Functional changes associated with drivers in chronic liver disease (exome) | H13: 338 | I13: passed | J13: v1.5 | K13: XP | L13: S4 | M13: 151 | N13: 151 | O13: 0.99999999 | P13: Twist Pulldown | Q13: 26 | R13: 35362787
A14: NovaSeq | B14: S4240 | C14: 6423 | D14: 3 | E14: 93296 | F14: Functional changes associated with drivers in chronic liver disease (exome) | H14: 338 | I14: passed | J14: v1.5 | K14: XP | L14: S4 | M14: 151 | N14: 151 | O14: 0.99999999 | P14: Twist Pulldown | Q14: 26 | R14: 34572410
A15: HiSeq | B15: S10332 | C15: 6644 | D15: 1 | E15: 93301 | F15: HCA Bone Marrow Wellcome LEAP RNA | I15: passed | O15: 1 | P15: Chromium single cell 5 prime | Q15: 2 | R15: 4519056
A16: HiSeq | B16: S10332 | C16: 6644 | D16: 2 | E16: 93301 | F16: HCA Bone Marrow Wellcome LEAP RNA | I16: passed | O16: 1 | P16: Chromium single cell 5 prime | Q16: 2 | R16: 4635952.5
A17: NovaSeq | B17: T10274 | C17: 6187 | D17: 1 | E17: 93378 | F17: Heron Project | H17: 545 | I17: passed | J17: v1.5 | K17: XP | L17: SP | M17: 221 | N17: 201 | O17: 0.99999974 | P17: Sanger_tailed_artic_v1_384 | Q17: 384 | R17: 511999.53
A18: NovaSeq | B18: T10274 | C18: 6187 | D18: 2 | E18: 93378 | F18: Heron Project | H18: 545 | I18: passed | J18: v1.5 | K18: XP | L18: SP | M18: 221 | N18: 201 | O18: 0.99999974 | P18: Sanger_tailed_artic_v1_384 | Q18: 384 | R18: 556005.76
A19: NovaSeq | B19: T10274 | C19: 6187 | D19: 1 | E19: 93381 | F19: Heron Project | H19: 545 | I19: passed | J19: v1.5 | K19: XP | L19: SP | M19: 221 | N19: 201 | O19: 0.99999998 | P19: Sanger_tailed_artic_v1_384 | Q19: 382 | R19: 534772.48
A20: NovaSeq | B20: T10274 | C20: 6187 | D20: 2 | E20: 93381 | F20: Heron Project | H20: 545 | I20: passed | J20: v1.5 | K20: XP | L20: SP | M20: 221 | N20: 201 | O20: 0.99999974 | P20: Sanger_tailed_artic_v1_384 | Q20: 384 | R20: 474191.07
A21: NovaSeq | B21: T10274 | C21: 6187 | D21: 1 | E21: 93382 | F21: Heron Project | H21: 545 | I21: passed | J21: v1.5 | K21: XP | L21: SP | M21: 221 | N21: 201 | O21: 0.99999974 | P21: Sanger_tailed_artic_v1_384 | Q21: 384 | R21: 557385.74
A22: NovaSeq | B22: T10274 | C22: 6187 | D22: 2 | E22: 93382 | F22: Heron Project | H22: 545 | I22: passed | J22: v1.5 | K22: XP | L22: SP | M22: 221 | N22: 201 | O22: 0.99999974 | P22: Sanger_tailed_artic_v1_384 | Q22: 384 | R22: 558268.67
A23: NovaSeq | B23: T10274 | C23: 6187 | D23: 1 | E23: 93383 | F23: Heron Project | H23: 545 | I23: passed | J23: v1.5 | K23: XP | L23: SP | M23: 221 | N23: 201 | O23: 0.99999974 | P23: Sanger_tailed_artic_v1_384 | Q23: 384 | R23: 515708.97
A24: NovaSeq | B24: T10274 | C24: 6187 | D24: 2 | E24: 93383 | F24: Heron Project | H24: 545 | I24: passed | J24: v1.5 | K24: XP | L24: SP | M24: 221 | N24: 201 | O24: 0.99999974 | P24: Sanger_tailed_artic_v1_384 | Q24: 384 | R24: 556082.06
A25: NovaSeq | B25: T10274 | C25: 6187 | D25: 1 | E25: 93384 | F25: Heron Project | H25: 545 | I25: passed | J25: v1.5 | K25: XP | L25: SP | M25: 221 | N25: 201 | O25: 0.99999974 | P25: Sanger_tailed_artic_v1_384 | Q25: 384 | R25: 541942.21
A26: NovaSeq | B26: T10274 | C26: 6187 | D26: 2 | E26: 93384 | F26: Heron Project | H26: 545 | I26: passed | J26: v1.5 | K26: XP | L26: SP | M26: 221 | N26: 201 | O26: 0.99999974 | P26: Sanger_tailed_artic_v1_384 | Q26: 384 | R26: 540373.43
A27: NovaSeq | B27: S4216 | C27: 6595 | D27: 1 | E27: 93290 | F27: HG_WC10162_Birth Cohort_MCS | H27: 330 | I27: passed | J27: v1 | K27: XP | L27: S4 | M27: 101 | N27: 101 | O27: 0.99999994 | P27: Agilent Pulldown | Q27: 96 | R27: 5997014.7
A28: NovaSeq | B28: S4216 | C28: 6595 | D28: 2 | E28: 93290 | F28: HG_WC10162_Birth Cohort_MCS | H28: 330 | I28: passed | J28: v1 | K28: XP | L28: S4 | M28: 101 | N28: 101 | O28: 0.99999994 | P28: Agilent Pulldown | Q28: 96 | R28: 5997183.7
... A38: NovaSeq | B38: S4360 | C38: 6595 | D38: 4 | E38: 93352 | F38: HG_WC10162_Birth Cohort_MCS | H38: 330 | I38: passed | J38: v1 | K38: XP | L38: S4 | M38: 101 | N38: 101 | O38: 0.99999994 | P38: Agilent Pulldown | Q38: 96 | R38: 5879089.7
A39: MiSeq | B39: S0910 | C39: 2984 | D39: 1 | E39: 93010 | F39: MQ R and D 2014 | G39: 600V3 | O39: 1 | P39: Pre-quality controlled | Q39: 37 | R39: 126135.22
A40: MiSeq | B40: S0910 | C40: 2984 | D40: 1 | E40: 93080 | F40: MQ R and D 2014 | G40: 600V3 | O40: 0.99999999 | P40: Pre-quality controlled | Q40: 49 | R40: 98693.367
A41: NovaSeq | B41: S0910 | C41: 2984 | D41: 4 | E41: 93296 | F41: MQ R and D 2014 | H41: 338 | I41: passed | J41: v1.5 | K41: XP | L41: S4 | M41: 151 | N41: 151 | O41: 0.84482757 | P41: Pre-quality controlled | Q41: 49 | R41: 10942318
A42: NovaSeq | B42: S10017 | C42: 6778 | D42: 1 | E42: 93242 | F42: Mutational variability in oesophagus in areas of high SCC incidence_WGS | H42: 338 | I42: passed | J42: v1.5 | K42: No XP | L42: S4 | M42: 151 | N42: 151 | O42: 0.99999996 | P42: Agilent Pulldown | Q42: 25
A43: NovaSeq | B43: S10017 | C43: 6778 | D43: 2 | E43: 93242 | F43: Mutational variability in oesophagus in areas of high SCC incidence_WGS | H43: 338 | I43: passed | J43: v1.5 | K43: No XP | L43: S4 | M43: 151 | N43: 151 | O43: 0.99999996 | P43: Agilent Pulldown | Q43: 25
A44: NovaSeq | B44: S10017 | C44: 6778 | D44: 3 | E44: 93242 | F44: Mutational variability in oesophagus in areas of high SCC incidence_WGS | H44: 338 | I44: passed | J44: v1.5 | K44: No XP | L44: S4 | M44: 151 | N44: 151 | O44: 0.99999996 | P44: Agilent Pulldown | Q44: 25
A45: NovaSeq | B45: S10017 | C45: 6778 | D45: 4 | E45: 93242 | F45: Mutational variability in oesophagus in areas of high SCC incidence_WGS | H45: 338 | I45: passed | J45: v1.5 | K45: No XP | L45: S4 | M45: 151 | N45: 151 | O45: 0.99999996 | P45: Agilent Pulldown | Q45: 25
A46: NovaSeq | B46: T10274 | C46: 6940 | D46: 1 | E46: 93379 | F46: RVI Programme - Heron Library | H46: 545 | I46: passed | J46: v1.5 | K46: XP | L46: SP | M46: 221 | N46: 201 | O46: 0.99999974 | P46: Sanger_tailed_artic_v1_384 | Q46: 384 | R46: 565047.62
A47: NovaSeq | B47: T10274 | C47: 6940 | D47: 2 | E47: 93379 | F47: RVI Programme - Heron Library | H47: 545 | I47: passed | J47: v1.5 | K47: XP | L47: SP | M47: 221 | N47: 201 | O47: 0.99999974 | P47: Sanger_tailed_artic_v1_384 | Q47: 384 | R47: 561630.7

Sheet Cell By Cell Cmp
A1: =new_billing_query_ungrouped!A1=original_billing_query!A1 -> TRUE | B1: =new_billing_query_ungrouped!B1=original_billing_query!B1 -> TRUE | C1: =new_billing_query_ungrouped!C1=original_billing_query!C1 -> TRUE | D1: =new_billing_query_ungrouped!D1=original_billing_query!D1 -> TRUE | E1: =new_billing_query_ungrouped!E1=original_billing_query!E1 -> TRUE | F1: =new_billing_query_ungrouped!F1=original_billing_query!F1 -> TRUE | G1: =new_billing_query_ungrouped!G1=original_billing_query!G1 -> TRUE | H1: =new_billing_query_ungrouped!H1=original_billing_query!H1 -> TRUE | ... R1: =new_billing_query_ungrouped!R1=original_billing_query!R1 -> TRUE
A2: =new_billing_query_ungrouped!A2=original_billing_query!A2 -> TRUE | B2: =new_billing_query_ungrouped!B2=original_billing_query!B2 -> TRUE | C2: =new_billing_query_ungrouped!C2=original_billing_query!C2 -> TRUE | D2: =new_billing_query_ungrouped!D2=original_billing_query!D2 -> TRUE | E2: =new_billing_query_ungrouped!E2=original_billing_query!E2 -> TRUE | F2: =new_billing_query_ungrouped!F2=original_billing_query!F2 -> TRUE | G2: =new_billing_query_ungrouped!G2=original_billing_query!G2 -> TRUE | H2: =new_billing_query_ungrouped!H2=original_billing_query!H2 -> TRUE | ... R2: =new_billing_query_ungrouped!R2=original_billing_query!R2 -> TRUE
A3: =new_billing_query_ungrouped!A3=original_billing_query!A3 -> TRUE | B3: =new_billing_query_ungrouped!B3=original_billing_query!B3 -> TRUE | C3: =new_billing_query_ungrouped!C3=original_billing_query!C3 -> TRUE | D3: =new_billing_query_ungrouped!D3=original_billing_query!D3 -> TRUE | E3: =new_billing_query_ungrouped!E3=original_billing_query!E3 -> TRUE | F3: =new_billing_query_ungrouped!F3=original_billing_query!F3 -> TRUE | G3: =new_billing_query_ungrouped!G3=original_billing_query!G3 -> TRUE | H3: =new_billing_query_ungrouped!H3=original_billing_query!H3 -> TRUE | ... R3: =new_billing_query_ungrouped!R3=original_billing_query!R3 -> TRUE
A4: =new_billing_query_ungrouped!A4=original_billing_query!A4 -> TRUE | B4: =new_billing_query_ungrouped!B4=original_billing_query!B4 -> TRUE | C4: =new_billing_query_ungrouped!C4=original_billing_query!C4 -> TRUE | D4: =new_billing_query_ungrouped!D4=original_billing_query!D4 -> TRUE | E4: =new_billing_query_ungrouped!E4=original_billing_query!E4 -> TRUE | F4: =new_billing_query_ungrouped!F4=original_billing_query!F4 -> TRUE | G4: =new_billing_query_ungrouped!G4=original_billing_query!G4 -> TRUE | H4: =new_billing_query_ungrouped!H4=original_billing_query!H4 -> TRUE | ... R4: =new_billing_query_ungrouped!R4=original_billing_query!R4 -> TRUE
A5: =new_billing_query_ungrouped!A5=original_billing_query!A5 -> TRUE | B5: =new_billing_query_ungrouped!B5=original_billing_query!B5 -> TRUE | C5: =new_billing_query_ungrouped!C5=original_billing_query!C5 -> TRUE | D5: =new_billing_query_ungrouped!D5=original_billing_query!D5 -> TRUE | E5: =new_billing_query_ungrouped!E5=original_billing_query!E5 -> TRUE | F5: =new_billing_query_ungrouped!F5=original_billing_query!F5 -> TRUE | G5: =new_billing_query_ungrouped!G5=original_billing_query!G5 -> TRUE | H5: =new_billing_query_ungrouped!H5=original_billing_query!H5 -> TRUE | ... R5: =new_billing_query_ungrouped!R5=original_billing_query!R5 -> TRUE
A6: =new_billing_query_ungrouped!A6=original_billing_query!A6 -> TRUE | B6: =new_billing_query_ungrouped!B6=original_billing_query!B6 -> TRUE | C6: =new_billing_query_ungrouped!C6=original_billing_query!C6 -> TRUE | D6: =new_billing_query_ungrouped!D6=original_billing_query!D6 -> TRUE | E6: =new_billing_query_ungrouped!E6=original_billing_query!E6 -> TRUE | F6: =new_billing_query_ungrouped!F6=original_billing_query!F6 -> TRUE | G6: =new_billing_query_ungrouped!G6=original_billing_query!G6 -> TRUE | H6: =new_billing_query_ungrouped!H6=original_billing_query!H6 -> TRUE | ... R6: =new_billing_query_ungrouped!R6=original_billing_query!R6 -> TRUE
A7: =new_billing_query_ungrouped!A7=original_billing_query!A7 -> TRUE | B7: =new_billing_query_ungrouped!B7=original_billing_query!B7 -> TRUE | C7: =new_billing_query_ungrouped!C7=original_billing_query!C7 -> TRUE | D7: =new_billing_query_ungrouped!D7=original_billing_query!D7 -> TRUE | E7: =new_billing_query_ungrouped!E7=original_billing_query!E7 -> TRUE | F7: =new_billing_query_ungrouped!F7=original_billing_query!F7 -> TRUE | G7: =new_billing_query_ungrouped!G7=original_billing_query!G7 -> TRUE | H7: =new_billing_query_ungrouped!H7=original_billing_query!H7 -> TRUE | ... R7: =new_billing_query_ungrouped!R7=original_billing_query!R7 -> TRUE
A8: =new_billing_query_ungrouped!A8=original_billing_query!A8 -> TRUE | B8: =new_billing_query_ungrouped!B8=original_billing_query!B8 -> TRUE | C8: =new_billing_query_ungrouped!C8=original_billing_query!C8 -> TRUE | D8: =new_billing_query_ungrouped!D8=original_billing_query!D8 -> TRUE | E8: =new_billing_query_ungrouped!E8=original_billing_query!E8 -> TRUE | F8: =new_billing_query_ungrouped!F8=original_billing_query!F8 -> TRUE | G8: =new_billing_query_ungrouped!G8=original_billing_query!G8 -> TRUE | H8: =new_billing_query_ungrouped!H8=original_billing_query!H8 -> TRUE | ... R8: =new_billing_query_ungrouped!R8=original_billing_query!R8 -> TRUE
A9: =new_billing_query_ungrouped!A9=original_billing_query!A9 -> TRUE | B9: =new_billing_query_ungrouped!B9=original_billing_query!B9 -> TRUE | C9: =new_billing_query_ungrouped!C9=original_billing_query!C9 -> TRUE | D9: =new_billing_query_ungrouped!D9=original_billing_query!D9 -> TRUE | E9: =new_billing_query_ungrouped!E9=original_billing_query!E9 -> TRUE | F9: =new_billing_query_ungrouped!F9=original_billing_query!F9 -> TRUE | G9: =new_billing_query_ungrouped!G9=original_billing_query!G9 -> TRUE | H9: =new_billing_query_ungrouped!H9=original_billing_query!H9 -> TRUE | ... R9: =new_billing_query_ungrouped!R9=original_billing_query!R9 -> TRUE
A10: =new_billing_query_ungrouped!A10=original_billing_query!A10 -> TRUE | B10: =new_billing_query_ungrouped!B10=original_billing_query!B10 -> TRUE | C10: =new_billing_query_ungrouped!C10=original_billing_query!C10 -> TRUE | D10: =new_billing_query_ungrouped!D10=original_billing_query!D10 -> TRUE | E10: =new_billing_query_ungrouped!E10=original_billing_query!E10 -> TRUE | F10: =new_billing_query_ungrouped!F10=original_billing_query!F10 -> TRUE | G10: =new_billing_query_ungrouped!G10=original_billing_query!G10 -> TRUE | H10: =new_billing_query_ungrouped!H10=original_billing_query!H10 -> TRUE | ... R10: =new_billing_query_ungrouped!R10=original_billing_query!R10 -> TRUE
A11: =new_billing_query_ungrouped!A11=original_billing_query!A11 -> TRUE | B11: =new_billing_query_ungrouped!B11=original_billing_query!B11 -> TRUE | C11: =new_billing_query_ungrouped!C11=original_billing_query!C11 -> TRUE | D11: =new_billing_query_ungrouped!D11=original_billing_query!D11 -> TRUE | E11: =new_billing_query_ungrouped!E11=original_billing_query!E11 -> TRUE | F11: =new_billing_query_ungrouped!F11=original_billing_query!F11 -> TRUE | G11: =new_billing_query_ungrouped!G11=original_billing_query!G11 -> TRUE | H11: =new_billing_query_ungrouped!H11=original_billing_query!H11 -> TRUE | ... R11: =new_billing_query_ungrouped!R11=original_billing_query!R11 -> TRUE
A12: =new_billing_query_ungrouped!A12=original_billing_query!A12 -> TRUE | B12: =new_billing_query_ungrouped!B12=original_billing_query!B12 -> TRUE | C12: =new_billing_query_ungrouped!C12=original_billing_query!C12 -> TRUE | D12: =new_billing_query_ungrouped!D12=original_billing_query!D12 -> TRUE | E12: =new_billing_query_ungrouped!E12=original_billing_query!E12 -> TRUE | F12: =new_billing_query_ungrouped!F12=original_billing_query!F12 -> TRUE | G12: =new_billing_query_ungrouped!G12=original_billing_query!G12 -> TRUE | H12: =new_billing_query_ungrouped!H12=original_billing_query!H12 -> TRUE | ... R12: =new_billing_query_ungrouped!R12=original_billing_query!R12 -> TRUE
... A57: =new_billing_query_ungrouped!A57=original_billing_query!A57 -> TRUE | B57: =new_billing_query_ungrouped!B57=original_billing_query!B57 -> TRUE | C57: =new_billing_query_ungrouped!C57=original_billing_query!C57 -> TRUE | D57: =new_billing_query_ungrouped!D57=original_billing_query!D57 -> TRUE | E57: =new_billing_query_ungrouped!E57=original_billing_query!E57 -> TRUE | F57: =new_billing_query_ungrouped!F57=original_billing_query!F57 -> TRUE | G57: =new_billing_query_ungrouped!G57=original_billing_query!G57 -> TRUE | H57: =new_billing_query_ungrouped!H57=original_billing_query!H57 -> TRUE | ... R57: =new_billing_query_ungrouped!R57=original_billing_query!R57 -> TRUE
